Workbook

Sheet SollIst Zeiterfassung
A1: Erklärung zum Tool: | D1: Teammitglieder | E1: Namen bitte eintragen | G1: Anzahl der Teammitglieder | I1: 3 | J1: Legende
A2: Zunächst Namen der Teammitglieder eintragen, sowie Anzahl und Arbeitsstunden für den Sprint | D2: 1 | E2: Sam Wagner | G2: Stunden pro Person pro Sprint | I2: 30 | J2: Haupttask
A3: Das Tool füllt dann selbst die entsprechenden Zellen. Werden keine Namen eingetragen, bleibt die entsprechende | D3: 2 | E3: Milenko Pekez | G3: Gesamtzeit für Team | I3: =I2*I1 -> 90 | J3: Subtask
A4: Spalte leer. | D4: 3 | E4: Delia Keller
A5: Formeln für Summen in Gesamtzeit für Sprint / Puffer / Restzeit müssen manuell erweitert werden | D5: 4
A8: Sprint 1 Zeiterfassung SOLL | D8: Teammitglieder
A9: ID | B9: Task | C9: Beschreibung | D9: =E2 -> Sam Wagner | E9: =E3 -> Milenko Pekez | F9: =E4 -> Delia Keller | G9: =E5 -> 0 | H9: Gesamtzeit
A10: SCRUM-55 | B10: SM1: Jira Dokumentation | C10: Als Scrum Master möchte ich das die Jira Dokumentation während des Sprints auf dem aktuellen Stand ist. | D10: 5
A11: SCRUM-28 | B11: INT: Jira Konfiguration | C11: Als Scrum Master möchte ich das Jira-Projekt vollständig konfigurieren, damit der PO den Fortschritt jederzeit einsehen kann. | D11: 13
A12: SCRUM-45 | B12: Epics anlegen
A13: SCRUM-46 | B13: User Stories mit Beschreibung und Abnahmekriterium anlegen
A14: SCRUM-47 | B14: Sprint 1 anlegen, Sprintziel eintragen, Stories und Tasks zuweisen
A15: SCRUM-48 | B15: POs einladen
A16: SCRUM-29 | B16: INT: Versionierung | C16: Als Team möchten wir einen Versionierung durch den Einsatz eines Git Repositories. | F16: 5
A17: SCRUM-30 | B17: INT: Coding- & Doku-Richtlinien | C17: Als Team möchten wir gemeinsame Coding- und Dokumentationsrichtlinien festlegen, damit wir konsistent arbeiten können. | F17: 5
A18: SCRUM-49 | B18: Guideline-Dokument in Confluence schreiben
A19: SCRUM-50 | B19: Im Team abstimmen und abspeichern
A20: SCRUM-24 | B20: US1: Kriterienkatalog | C20: Als Stadtmitarbeiter/in möchte ich einen Kriterienkatalog einsehen, damit ich Maßnahmen objektiv vergleichen kann. | D20: 21
A21: SCRUM-37 | B21: Kriterien recherchieren & Liste erstellen
A22: SCRUM-38 | B22: Jedes Kriterium schriftlich definieren
A23: SCRUM-39 | B23: Team-Review des Entwurfs & Überarbeitung
A24: SCRUM-25 | B24: US2: Metrik & Datenquelle je Kriterium | C24: Als Team möchten wir für jedes Kriterium einen Metrik und Datenquellen festlegen, damit die Evaluation nachvollziehbar ist. | E24: 21
A25: SCRUM-40 | B25: Verfügbare Datenquellen am Lederhof recherchieren
A26: SCRUM-41 | B26: Metrik-Tabellen erstellen und in Kriterienkatalog einfügen
A27: SCRUM-26 | B27: US3: Maßnahmen dokumentieren | C27: Als Stadtmitarbeiter/in möchte ich bisherige Maßnahmen am Lederhof als Übersicht einsehen | E27: 13
A28: SCRUM-42 | B28: Maßnahmen aus DASU-Pitch-Folien extrahieren
A29: SCRUM-43 | B29: Quellen sichten und auswerten
A30: SCRUM-44 | B30: Recherche Kurzbericht schreiben und abspeichern
B33: Gesamtzeit für Sprint | C33: Summe aus D10:D22 (Erweitern bei mehr Tasks) | D33: =IF(E2<>"",SUM(D10:D32),"") -> 39 | E33: =IF(E3<>"",SUM(E10:E32),"") -> 34 | F33: =IF(E4<>"",SUM(F10:F32),"") -> 10 | G33: =IF(E5<>"",SUM(G10:G32),"") | H33: =SUM(D33:G33) -> 83
B34: Puffer | C34: 30 Arbeitsstunden - individuelle Arbeitszeit; Berechnung wird erst angezeigt, wenn Namen angegeben wurden | D34: =IF(E2<>"",I2-D33,"") -> -9 | E34: =IF(E3<>"",I2-E33,"") -> -4 | F34: =IF(E4<>"",I2-F33,"") -> 20 | H34: =I3-H33 -> 7
A37: Sprint 1 Zeiterfassung IST | D37: Teammitglieder
A38: ID | B38: Task | C38: Beschreibung | D38: =E2 -> Sam Wagner | E38: =E3 -> Milenko Pekez | F38: =E4 -> Delia Keller | G38: =E5 -> 0 | H38: Gesamtzeit
A39: SCRUM-55 | B39: SM1: Jira Dokumentation | C39: Als Scrum Master möchte ich das Jira-Projekt vollständig konfigurieren, damit der PO den Fortschritt jederzeit einsehen kann. | F39: 3 | I39: Kommentar DK: Anlage Zeitplanung, Anlage Sprint 2
A40: SCRUM-28 | B40: INT: Jira Konfiguration | C40: Als Scrum Master möchte ich das Jira-Projekt vollständig konfigurieren, damit der PO den Fortschritt jederzeit einsehen kann.
A41: SCRUM-45 | B41: Epics anlegen
A42: SCRUM-46 | B42: User Stories mit Beschreibung und Abnahmekriterium anlegen
A43: SCRUM-47 | B43: Sprint 1 anlegen, Sprintziel eintragen, Stories und Tasks zuweisen
A44: SCRUM-48 | B44: POs einladen
A45: SCRUM-29 | B45: INT: Versionierung | C45: Als Team möchten wir einen Versionierung durch den Einsatz eines Git Repositories. | F45: 8
A46: SCRUM-30 | B46: INT: Coding- & Doku-Richtlinien | C46: Als Team möchten wir gemeinsame Coding- und Dokumentationsrichtlinien festlegen, damit wir konsistent arbeiten können. | F46: 5
...

Sheet wöchentliche Zeitplanung
A1: Erklärung: Zunächst Sprintstart und Sprintende angeben; Danach müssen nur die einzelnen Zellen durch die Teammitglieder mit ihren indivuduellen Arbeitszeiten befüllt werden
A2: Kommentar: Bei Verwendung des Tools in Sheets muss in E4 die Formel angepasst werden. In Excel sollte man die ISOKALENDERWOCHE()-Funktion nutzen; in Google Sheets dagegen ISOWEEKNUM()
A3: Zeitplanung | B3: Sprintstart | C3: 44673 | D3: Sprintende | E3: 44693 | F3: # Wochen | G3: =ROUND(G4/7,0)+1 -> 4
D4: Kalenderwoche | E4: =IF(C3<>"",_xlfn.ISOWEEKNUM(C3),"") -> 16 | F4: # Tage | G4: =E3-C3 -> 20
D5: Jahr | E5: =IF(C3<>"",YEAR(C3),"") -> 2022
A7: Kalenderwochen | B7: Sprint | C7: Mo | D7: Di | E7: Mi | F7: Do | G7: Fr | H7: Sa | I7: So
A8: =E4 -> 16 | B8: Woche 1 | C8: =DATE(E5,1,1)-WEEKDAY(DATE(E5,1,1),2)+1+((A8+IF(WEEKDAY(DATE(E5,1,1),2)>4,0,-1))*7) -> 44669 | D8: =C8+1 -> 44670 | E8: =D8+1 -> 44671 | F8: =E8+1 -> 44672 | G8: =F8+1 -> 44673 | H8: =G8+1 -> 44674 | I8: =H8+1 -> 44675 | J8: Summe/Woche | K8: Gesamtzeit im Sprint
B9: ='SollIst Zeiterfassung'!E2 -> Sam Wagner | J9: =SUM(C9:I9) -> 0 | K9: Teammitglieder
B10: ='SollIst Zeiterfassung'!E3 -> Milenko Pekez | J10: =SUM(C10:I10) -> 0 | K10: ='SollIst Zeiterfassung'!E2 -> Sam Wagner | L10: ='SollIst Zeiterfassung'!E3 -> Milenko Pekez | M10: ='SollIst Zeiterfassung'!E4 -> Delia Keller | N10: ='SollIst Zeiterfassung'!E5 -> 0
B11: ='SollIst Zeiterfassung'!E4 -> Delia Keller | J11: =SUM(C11:I11) -> 0 | K11: =IF(K10<>"",SUM(J9,J15,J21,J27),"") -> 0 | L11: =IF(L10<>"",SUM(J10,J16,J22,J28),"") -> 0 | M11: =IF(M10<>"",SUM(J11,J17,J23,J29),"") -> 0 | N11: =IF(N10<>"",SUM(J12,J18,J24,J30),"") -> 0
B12: ='SollIst Zeiterfassung'!E5 -> 0 | J12: =SUM(C12:I12) -> 0
B13: Tagessumme | C13: =SUM(C9:C12) -> 0 | D13: =SUM(D9:D12) -> 0 | E13: =SUM(E9:E12) -> 0 | F13: =SUM(F9:F12) -> 0 | G13: =SUM(G9:G12) -> 0 | H13: =SUM(H9:H12) -> 0 | I13: =SUM(I9:I12) -> 0 | J13: =SUM(J9:J12) -> 0
A14: =IF(G3>=2,E4+1,"") -> 17 | B14: Woche 2 | C14: =DATE(E5,1,1)-WEEKDAY(DATE(E5,1,1),2)+1+((A14+IF(WEEKDAY(DATE(E5,1,1),2)>4,0,-1))*7) -> 44676 | D14: =C14+1 -> 44677 | E14: =D14+1 -> 44678 | F14: =E14+1 -> 44679 | G14: =F14+1 -> 44680 | H14: =G14+1 -> 44681 | I14: =H14+1 -> 44682
B15: ='SollIst Zeiterfassung'!E2 -> Sam Wagner | J15: =SUM(C15:I15) -> 0
B16: ='SollIst Zeiterfassung'!E3 -> Milenko Pekez | J16: =SUM(C16:I16) -> 0
B17: ='SollIst Zeiterfassung'!E4 -> Delia Keller | J17: =SUM(C17:I17) -> 0
B18: ='SollIst Zeiterfassung'!E5 -> 0 | J18: =SUM(C18:I18) -> 0
B19: Tagessumme | C19: =SUM(C15:C18) -> 0 | D19: =SUM(D15:D18) -> 0 | E19: =SUM(E15:E18) -> 0 | F19: =SUM(F15:F18) -> 0 | G19: =SUM(G15:G18) -> 0 | H19: =SUM(H15:H18) -> 0 | I19: =SUM(I15:I18) -> 0 | J19: =SUM(J15:J18) -> 0
A20: =IF(G3>=3,E4+2,"") -> 18 | B20: Woche 3 | C20: =DATE(E5,1,1)-WEEKDAY(DATE(E5,1,1),2)+1+((A20+IF(WEEKDAY(DATE(E5,1,1),2)>4,0,-1))*7) -> 44683 | D20: =C20+1 -> 44684 | E20: =D20+1 -> 44685 | F20: =E20+1 -> 44686 | G20: =F20+1 -> 44687 | H20: =G20+1 -> 44688 | I20: =H20+1 -> 44689
B21: ='SollIst Zeiterfassung'!E2 -> Sam Wagner | J21: =SUM(C21:I21) -> 0
B22: ='SollIst Zeiterfassung'!E3 -> Milenko Pekez | J22: =SUM(C22:I22) -> 0
B23: ='SollIst Zeiterfassung'!E4 -> Delia Keller | J23: =SUM(C23:I23) -> 0
B24: ='SollIst Zeiterfassung'!E5 -> 0 | J24: =SUM(C24:I24) -> 0
B25: Tagessumme | C25: =SUM(C21:C24) -> 0 | D25: =SUM(D21:D24) -> 0 | E25: =SUM(E21:E24) -> 0 | F25: =SUM(F21:F24) -> 0 | G25: =SUM(G21:G24) -> 0 | H25: =SUM(H21:H24) -> 0 | I25: =SUM(I21:I24) -> 0 | J25: =SUM(J21:J24) -> 0
A26: =IF(G3>3,E4+3,"") -> 19 | B26: Woche 4 | C26: =DATE(E5,1,1)-WEEKDAY(DATE(E5,1,1),2)+1+((A26+IF(WEEKDAY(DATE(E5,1,1),2)>4,0,-1))*7) -> 44690 | D26: =C26+1 -> 44691 | E26: =D26+1 -> 44692 | F26: =E26+1 -> 44693 | G26: =F26+1 -> 44694 | H26: =G26+1 -> 44695 | I26: =H26+1 -> 44696
B27: ='SollIst Zeiterfassung'!E2 -> Sam Wagner | J27: =SUM(C27:I27) -> 0
B28: ='SollIst Zeiterfassung'!E3 -> Milenko Pekez | J28: =SUM(C28:I28) -> 0
B29: ='SollIst Zeiterfassung'!E4 -> Delia Keller | J29: =SUM(C29:I29) -> 0
B30: ='SollIst Zeiterfassung'!E5 -> 0 | J30: =SUM(C30:I30) -> 0
B31: Tagessumme | C31: =SUM(C27:C30) -> 0 | D31: =SUM(D27:D30) -> 0 | E31: =SUM(E27:E30) -> 0 | F31: =SUM(F27:F30) -> 0 | G31: =SUM(G27:G30) -> 0 | H31: =SUM(H27:H30) -> 0 | I31: =SUM(I27:I30) -> 0 | J31: =SUM(J27:J30) -> 0

Sheet Burndown Chart
A1: Erklärung: nur befüllen der Arbeitsleistung pro Tag notwendig. Die restlichen Zellen aktualisieren sich selbst, Tagessummen aus der wöchentlichen Zeitplanung per "copy/paste" in Arbeitsleistung pro Tag übertragen
A2: Sprint | B2: # Tage im Sprint | C2: ='wöchentliche Zeitplanung'!G4 -> 20
B3: # Stunden im Sprint | C3: ='SollIst Zeiterfassung'!I3 -> 90
B4: Ideale Workload pro Tag | C4: =C3/C2 -> 4.5
B5: Tag | C5: 1 | D5: =IF(AND(C5+1<='wöchentliche Zeitplanung'!G4, C5<>""),C5+1,"") -> 2 | E5: =IF(AND(D5+1<='wöchentliche Zeitplanung'!G4, D5<>""),D5+1,"") -> 3 | F5: =IF(AND(E5+1<='wöchentliche Zeitplanung'!G4, E5<>""),E5+1,"") -> 4 | G5: =IF(AND(F5+1<='wöchentliche Zeitplanung'!G4, F5<>""),F5+1,"") -> 5 | H5: =IF(AND(G5+1<='wöchentliche Zeitplanung'!G4, G5<>""),G5+1,"") -> 6 | I5: =IF(AND(H5+1<='wöchentliche Zeitplanung'!G4, H5<>""),H5+1,"") -> 7 | J5: =IF(AND(I5+1<='wöchentliche Zeitplanung'!G4, I5<>""),I5+1,"") -> 8 | K5: =IF(AND(J5+1<='wöchentliche Zeitplanung'!G4, J5<>""),J5+1,"") -> 9 | L5: =IF(AND(K5+1<='wöchentliche Zeitplanung'!G4, K5<>""),K5+1,"") -> 10 | M5: =IF(AND(L5+1<='wöchentliche Zeitplanung'!G4, L5<>""),L5+1,"") -> 11 | N5: =IF(AND(M5+1<='wöchentliche Zeitplanung'!G4, M5<>""),M5+1,"") -> 12 | O5: =IF(AND(N5+1<='wöchentliche Zeitplanung'!G4, N5<>""),N5+1,"") -> 13 | P5: =IF(AND(O5+1<='wöchentliche Zeitplanung'!G4, O5<>""),O5+1,"") -> 14 | Q5: =IF(AND(P5+1<='wöchentliche Zeitplanung'!G4, P5<>""),P5+1,"") -> 15 | R5: =IF(AND(Q5+1<='wöchentliche Zeitplanung'!G4, Q5<>""),Q5+1,"") -> 16 | S5: =IF(AND(R5+1<='wöchentliche Zeitplanung'!G4, R5<>""),R5+1,"") -> 17 | T5: =IF(AND(S5+1<='wöchentliche Zeitplanung'!G4, S5<>""),S5+1,"") -> 18 | U5: =IF(AND(T5+1<='wöchentliche Zeitplanung'!G4, T5<>""),T5+1,"") -> 19 | V5: =IF(AND(U5+1<='wöchentliche Zeitplanung'!G4, U5<>""),U5+1,"") -> 20 | W5: =IF(AND(V5+1<='wöchentliche Zeitplanung'!G4, V5<>""),V5+1,"") | X5: =IF(AND(W5+1<='wöchentliche Zeitplanung'!G4, W5<>""),W5+1,"") -> #VALUE! | Y5: =IF(AND(X5+1<='wöchentliche Zeitplanung'!G4, X5<>""),X5+1,"") -> #VALUE! | Z5: =IF(AND(Y5+1<='wöchentliche Zeitplanung'!G4, Y5<>""),Y5+1,"") -> #VALUE! | AA5: =IF(AND(Z5+1<='wöchentliche Zeitplanung'!G4, Z5<>""),Z5+1,"") -> #VALUE! | AB5: =IF(AND(AA5+1<='wöchentliche Zeitplanung'!G4, AA5<>""),AA5+1,"") -> #VALUE! | AC5: =IF(AND(AB5+1<='wöchentliche Zeitplanung'!G4, AB5<>""),AB5+1,"") -> #VALUE! | AD5: =IF(AND(AC5+1<='wöchentliche Zeitplanung'!G4, AC5<>""),AC5+1,"") -> #VALUE! | AE5: =IF(AND(AD5+1<='wöchentliche Zeitplanung'!G4, AD5<>""),AD5+1,"") -> #VALUE!
B6: Arbeitsleistung pro Tag
B7: restliche Stunden | C7: =C3-C6 -> 90 | D7: =IF(D5<>"",C7-D6,"") -> 90 | E7: =IF(E5<>"",D7-E6,"") -> 90 | F7: =IF(F5<>"",E7-F6,"") -> 90 | G7: =IF(G5<>"",F7-G6,"") -> 90 | H7: =IF(H5<>"",G7-H6,"") -> 90 | I7: =IF(I5<>"",H7-I6,"") -> 90 | J7: =IF(J5<>"",I7-J6,"") -> 90 | K7: =IF(K5<>"",J7-K6,"") -> 90 | ... AE7: =IF(AE5<>"",AD7-AE6,"") -> #VALUE!
B8: Ideale Workload | C8: =IF(C5<>"",C3-C4,"") -> 85.5 | D8: =IF(D5<>"",C8-C4,"") -> 81 | E8: =IF(E5<>"",D8-C4,"") -> 76.5 | F8: =IF(F5<>"",E8-C4,"") -> 72 | G8: =IF(G5<>"",F8-C4,"") -> 67.5 | H8: =IF(H5<>"",G8-C4,"") -> 63 | I8: =IF(I5<>"",H8-C4,"") -> 58.5 | J8: =IF(J5<>"",I8-C4,"") -> 54 | K8: =IF(K5<>"",J8-C4,"") -> 49.5 | L8: =IF(L5<>"",K8-C4,"") -> 45 | M8: =IF(M5<>"",L8-C4,"") -> 40.5 | N8: =IF(N5<>"",M8-C4,"") -> 36 | O8: =IF(O5<>"",N8-C4,"") -> 31.5 | P8: =IF(P5<>"",O8-C4,"") -> 27 | Q8: =IF(Q5<>"",P8-C4,"") -> 22.5 | R8: =IF(R5<>"",Q8-C4,"") -> 18 | S8: =IF(S5<>"",R8-C4,"") -> 13.5 | T8: =IF(T5<>"",S8-C4,"") -> 9 | U8: =IF(U5<>"",T8-C4,"") -> 4.5 | V8: =IF(V5<>"",U8-C4,"") -> 0 | W8: =IF(W5<>"",V8-C4,"") | X8: =IF(X5<>"",W8-C4,"") -> #VALUE! | Y8: =IF(Y5<>"",X8-C4,"") -> #VALUE! | Z8: =IF(Z5<>"",Y8-C4,"") -> #VALUE! | AA8: =IF(AA5<>"",Z8-C4,"") -> #VALUE! | AB8: =IF(AB5<>"",AA8-C4,"") -> #VALUE! | AC8: =IF(AC5<>"",AB8-C4,"") -> #VALUE! | AD8: =IF(AD5<>"",AC8-C4,"") -> #VALUE! | AE8: =IF(AE5<>"",AD8-C4,"") -> #VALUE!
A28: Erklärung Burndown-Diagramm: Zeilen 6 "Tag", 7 "restliche Stunden", 8 "ideale Workload" markieren -> Einfügen Dropdownmenü öffnen -> Diagramm -> Liniendiagramm
